Workbook

Sheet personalist
A1: Name | B1: Position | C1: labor$/day
A2: Alexander H | B2: Manager/senior Engineer | C2: =VLOOKUP(B2, $D$3:$E$9, 2, FALSE) -> 671 | D2: position | E2: labor $/day
A3: Amanda S | B3: Remote senior | C3: =VLOOKUP(B3, $D$3:$E$9, 2, FALSE) -> 671 | D3: Technician I | E3: 295
A4: Andy R | B4: Engineer/supervisor | C4: =VLOOKUP(B4, $D$3:$E$9, 2, FALSE) -> 536 | D4: Technician II | E4: 456
A5: Angie G | B5: Technician II | C5: =VLOOKUP(B5, $D$3:$E$9, 2, FALSE) -> 456 | D5: Welder | E5: 469
A6: Ashton F | B6: Technician II | C6: =VLOOKUP(B6, $D$3:$E$9, 2, FALSE) -> 456 | D6: Engineer/supervisor | E6: 536
A7: Brian K | B7: Manager/senior Engineer | C7: =VLOOKUP(B7, $D$3:$E$9, 2, FALSE) -> 671 | D7: Manager/senior Engineer | E7: 671
A8: Brian M | B8: Engineer/supervisor | C8: =VLOOKUP(B8, $D$3:$E$9, 2, FALSE) -> 536 | D8: Remote mid engineer | E8: 536
A9: Brian V | B9: Technician II | C9: =VLOOKUP(B9, $D$3:$E$9, 2, FALSE) -> 456 | D9: Remote senior | E9: 671
A10: Carol W | B10: Remote senior | C10: =VLOOKUP(B10, $D$3:$E$9, 2, FALSE) -> 671
A11: Chris H | B11: Engineer/supervisor | C11: =VLOOKUP(B11, $D$3:$E$9, 2, FALSE) -> 536
A12: Christopher M | B12: Technician II | C12: =VLOOKUP(B12, $D$3:$E$9, 2, FALSE) -> 456
A13: Cole M | B13: Technician II | C13: =VLOOKUP(B13, $D$3:$E$9, 2, FALSE) -> 456
A14: Eric C | B14: Remote mid engineer | C14: =VLOOKUP(B14, $D$3:$E$9, 2, FALSE) -> 536
A15: Frank A | B15: Technician II | C15: =VLOOKUP(B15, $D$3:$E$9, 2, FALSE) -> 456
A16: Gordon D | B16: Remote senior | C16: =VLOOKUP(B16, $D$3:$E$9, 2, FALSE) -> 671
A17: Greg S | B17: Technician II | C17: =VLOOKUP(B17, $D$3:$E$9, 2, FALSE) -> 456
A18: Howard H | B18: Technician II | C18: =VLOOKUP(B18, $D$3:$E$9, 2, FALSE) -> 456
A19: Iain C | B19: Remote senior | C19: =VLOOKUP(B19, $D$3:$E$9, 2, FALSE) -> 671
A20: Jason C | B20: Remote senior | C20: =VLOOKUP(B20, $D$3:$E$9, 2, FALSE) -> 671
A21: Joe F | B21: Technician II | C21: =VLOOKUP(B21, $D$3:$E$9, 2, FALSE) -> 456
... A35: Wyatt S | B35: Welder | C35: =VLOOKUP(B35, $D$3:$E$9, 2, FALSE) -> 469

Sheet weekly hours
B1: VACATION | C1: END DATE | D1: =_xlfn.XLOOKUP(D$3, personalist!$A:$A, personalist!$B:$B, NA()) -> Remote senior | E1: =_xlfn.XLOOKUP(E$3, personalist!$A:$A, personalist!$B:$B, NA()) -> Remote senior | F1: =_xlfn.XLOOKUP(F$3, personalist!$A:$A, personalist!$B:$B, NA()) -> Remote senior | G1: =_xlfn.XLOOKUP(G$3, personalist!$A:$A, personalist!$B:$B, NA()) -> Remote senior | H1: =_xlfn.XLOOKUP(H$3, personalist!$A:$A, personalist!$B:$B, NA()) -> Remote mid engineer | I1: =_xlfn.XLOOKUP(I$3, personalist!$A:$A, personalist!$B:$B, NA()) -> Remote mid engineer | J1: =_xlfn.XLOOKUP(J$3, personalist!$A:$A, personalist!$B:$B, NA()) -> Remote mid engineer | K1: =_xlfn.XLOOKUP(K$3, personalist!$A:$A, personalist!$B:$B, NA()) -> Remote senior | ... X1: =_xlfn.XLOOKUP(X$3, personalist!$A:$A, personalist!$B:$B, NA()) -> Technician II
A2: Salary $/day | D2: =_xlfn.XLOOKUP(D$3, personalist!$A:$A, personalist!$C:$C, NA()) -> 671 | E2: =_xlfn.XLOOKUP(E$3, personalist!$A:$A, personalist!$C:$C, NA()) -> 671 | F2: =_xlfn.XLOOKUP(F$3, personalist!$A:$A, personalist!$C:$C, NA()) -> 671 | G2: =_xlfn.XLOOKUP(G$3, personalist!$A:$A, personalist!$C:$C, NA()) -> 671 | H2: =_xlfn.XLOOKUP(H$3, personalist!$A:$A, personalist!$C:$C, NA()) -> 536 | I2: =_xlfn.XLOOKUP(I$3, personalist!$A:$A, personalist!$C:$C, NA()) -> 536 | J2: =_xlfn.XLOOKUP(J$3, personalist!$A:$A, personalist!$C:$C, NA()) -> 536 | K2: =_xlfn.XLOOKUP(K$3, personalist!$A:$A, personalist!$C:$C, NA()) -> 671 | ... X2: =_xlfn.XLOOKUP(X$3, personalist!$A:$A, personalist!$C:$C, NA()) -> 456
A3: Week # | B3: Start Date | C3: End Date | D3: Carol W | E3: Iain C | F3: Gordon D | G3: Jason C | H3: Eric C | I3: Luis Z | J3: Alsa G | K3: Amanda S | L3: Brian K | M3: Jonathan R | N3: Brian M | O3: Levi W | P3: Andy R | Q3: Mike C | R3: Luke G | S3: Vu T | T3: Tony M | U3: Wyatt S | V3: Ryan O | W3: Ashton F | X3: Frank A
A4: 1 | B4: 45754 | C4: =B4+6 -> 45760 | G4: 60 | H4: 80 | J4: 40
A5: 2 | B5: =B4+7 -> 45761 | C5: =B5+6 -> 45767 | H5: 20
A6: 3 | B6: =B5+7 -> 45768 | C6: =B6+6 -> 45774
A7: 4 | B7: =B6+7 -> 45775 | C7: =B7+6 -> 45781
A8: 5 | B8: =B7+7 -> 45782 | C8: =B8+6 -> 45788
A9: 6 | B9: =B8+7 -> 45789 | C9: =B9+6 -> 45795
A10: 7 | B10: =B9+7 -> 45796 | C10: =B10+6 -> 45802 | G10: 10 | H10: 30 | J10: 8
A11: 8 | B11: =B10+7 -> 45803 | C11: =B11+6 -> 45809
A12: 9 | B12: =B11+7 -> 45810 | C12: =B12+6 -> 45816
A13: 10 | B13: =B12+7 -> 45817 | C13: =B13+6 -> 45823 | G13: 10 | H13: 20
A14: 11 | B14: =B13+7 -> 45824 | C14: =B14+6 -> 45830 | H14: 20
A15: 12 | B15: =B14+7 -> 45831 | C15: =B15+6 -> 45837
A16: 13 | B16: =B15+7 -> 45838 | C16: =B16+6 -> 45844 | G16: 10 | H16: 20 | P16: 32
A17: 14 | B17: =B16+7 -> 45845 | C17: =B17+6 -> 45851 | P17: 40 | Q17: 8 | R17: 8
A18: 15 | B18: =B17+7 -> 45852 | C18: =B18+6 -> 45858 | H18: 16 | P18: 40 | Q18: 40 | R18: 40
A19: 16 | B19: =B18+7 -> 45859 | C19: =B19+6 -> 45865 | M19: 16 | P19: 40 | Q19: 40 | R19: 40
A20: 17 | B20: =B19+7 -> 45866 | C20: =B20+6 -> 45872 | M20: 32 | P20: 40 | Q20: 40 | R20: 40
A21: 18 | B21: =B20+7 -> 45873 | C21: =B21+6 -> 45879 | P21: 40 | Q21: 40 | R21: 40 | S21: 40
A22: 19 | B22: =B21+7 -> 45880 | C22: =B22+6 -> 45886 | M22: 40 | P22: 40 | Q22: 40 | R22: 40 | S22: 40
A23: 20 | B23: =B22+7 -> 45887 | C23: =B23+6 -> 45893 | M23: 40 | P23: 40 | Q23: 40 | R23: 40 | S23: 40
A24: 21 | B24: =B23+7 -> 45894 | C24: =B24+6 -> 45900 | G24: 8 | H24: 16 | I24: 8 | M24: 24 | Q24: 40 | R24: 32 | S24: 40
A25: 22 | B25: =B24+7 -> 45901 | C25: =B25+6 -> 45907 | G25: 16 | H25: 24 | I25: 8 | S25: 40
A26: 23 | B26: =B25+7 -> 45908 | C26: =B26+6 -> 45914 | G26: 8 | H26: 30 | I26: 6 | M26: 40 | P26: 32 | S26: 40
A27: 24 | B27: =B26+7 -> 45915 | C27: =B27+6 -> 45921 | G27: 5 | H27: 10 | I27: 1 | M27: 40 | O27: 40 | P27: 40 | Q27: 40 | R27: 40 | S27: 40 | V27: 40
A28: 25 | B28: =B27+7 -> 45922 | C28: =B28+6 -> 45928 | G28: 6 | I28: 1 | O28: 40 | P28: 40 | Q28: 40 | R28: 40 | V28: 16
A29: 26 | B29: =B28+7 -> 45929 | C29: =B29+6 -> 45935 | G29: 1 | I29: 1 | O29: 24 | P29: 40 | Q29: 40 | R29: 40 | S29: 40 | V29: =40-16 -> 24
A30: 27 | B30: =B29+7 -> 45936 | C30: =B30+6 -> 45942 | G30: 1 | I30: 1 | P30: 40 | Q30: 40
A31: 28 | B31: =B30+7 -> 45943 | C31: =B31+6 -> 45949 | G31: 1 | H31: 5 | I31: 1 | O31: 40 | P31: 40 | Q31: 40 | V31: 40
A32: 29 | B32: =B31+7 -> 45950 | C32: =B32+6 -> 45956 | I32: 1 | L32: 32 | O32: 40 | P32: 40 | Q32: 40 | R32: 40 | V32: 40
A33: 30 | B33: =B32+7 -> 45957 | C33: =B33+6 -> 45963 | I33: 1 | P33: 40 | Q33: 40 | R33: 40 | V33: 40
A34: 31 | B34: =B33+7 -> 45964 | C34: =B34+6 -> 45970 | I34: 1 | O34: 8 | P34: 40 | Q34: 40
A35: 32 | B35: =B34+7 -> 45971 | C35: =B35+6 -> 45977 | I35: 1 | O35: 40 | R35: 40 | S35: 32 | V35: 40
A36: 33 | B36: =B35+7 -> 45978 | C36: =B36+6 -> 45984 | H36: 1 | I36: 1 | O36: 40 | R36: 40 | S36: 40 | V36: 40
A37: 34 | B37: =B36+7 -> 45985 | C37: =B37+6 -> 45991 | I37: 1 | P37: 16
A38: 35 | B38: =B37+7 -> 45992 | C38: =B38+6 -> 45998 | I38: 1 | O38: 40 | P38: 40 | Q38: 40 | R38: 40
A39: 36 | B39: =B38+7 -> 45999 | C39: =B39+6 -> 46005 | L39: 40 | O39: 40 | P39: 40 | Q39: 40 | R39: 40 | V39: 40
A40: 37 | B40: =B39+7 -> 46006 | C40: =B40+6 -> 46012 | L40: 40 | O40: 40 | P40: 40 | Q40: 40 | R40: 40 | T40: 40 | V40: 40
...

Sheet labor Cost
A1: ='weekly hours'!A1 -> 0 | D1: ='weekly hours'!D1 -> Remote senior | E1: ='weekly hours'!E1 -> Remote senior | F1: ='weekly hours'!F1 -> Remote senior | G1: ='weekly hours'!G1 -> Remote senior | H1: ='weekly hours'!H1 -> Remote mid engineer | I1: ='weekly hours'!I1 -> Remote mid engineer | J1: ='weekly hours'!J1 -> Remote mid engineer | K1: ='weekly hours'!K1 -> Remote senior | ... V1: ='weekly hours'!V1 -> Welder
A2: ='weekly hours'!A2 -> Salary $/day | D2: ='weekly hours'!D2 -> 671 | E2: ='weekly hours'!E2 -> 671 | F2: ='weekly hours'!F2 -> 671 | G2: ='weekly hours'!G2 -> 671 | H2: ='weekly hours'!H2 -> 536 | I2: ='weekly hours'!I2 -> 536 | J2: ='weekly hours'!J2 -> 536 | K2: ='weekly hours'!K2 -> 671 | ... V2: ='weekly hours'!V2 -> 469
A3: ='weekly hours'!A3 -> Week # | B3: ='weekly hours'!B3 -> Start Date | C3: ='weekly hours'!C3 -> End Date | D3: ='weekly hours'!D3 -> Carol W | E3: ='weekly hours'!E3 -> Iain C | F3: ='weekly hours'!F3 -> Gordon D | G3: ='weekly hours'!G3 -> Jason C | H3: ='weekly hours'!H3 -> Eric C | ... V3: ='weekly hours'!V3 -> Ryan O
A4: ='weekly hours'!A4 -> 1 | B4: ='weekly hours'!B4 -> 45754 | C4: ='weekly hours'!C4 -> 45760 | D4: =IF('weekly hours'!D4=0," ",'weekly hours'!D4/8*'weekly hours'!D$2) | E4: =IF('weekly hours'!E4=0," ",'weekly hours'!E4/8*'weekly hours'!E$2) | F4: =IF('weekly hours'!F4=0," ",'weekly hours'!F4/8*'weekly hours'!F$2) | G4: =IF('weekly hours'!G4=0," ",'weekly hours'!G4/8*'weekly hours'!G$2) -> 5032.5 | H4: =IF('weekly hours'!H4=0," ",'weekly hours'!H4/8*'weekly hours'!H$2) -> 5360 | I4: =IF('weekly hours'!I4=0," ",'weekly hours'!I4/8*'weekly hours'!I$2) | J4: =IF('weekly hours'!J4=0," ",'weekly hours'!J4/8*'weekly hours'!J$2) -> 2680 | K4: =IF('weekly hours'!K4=0," ",'weekly hours'!K4/8*'weekly hours'!K$2) | ... V4: =IF('weekly hours'!V4=0," ",'weekly hours'!V4/8*'weekly hours'!V$2)
A5: ='weekly hours'!A5 -> 2 | B5: ='weekly hours'!B5 -> 45761 | C5: ='weekly hours'!C5 -> 45767 | D5: =IF('weekly hours'!D5=0," ",'weekly hours'!D5/8*'weekly hours'!D$2) | E5: =IF('weekly hours'!E5=0," ",'weekly hours'!E5/8*'weekly hours'!E$2) | F5: =IF('weekly hours'!F5=0," ",'weekly hours'!F5/8*'weekly hours'!F$2) | G5: =IF('weekly hours'!G5=0," ",'weekly hours'!G5/8*'weekly hours'!G$2) | H5: =IF('weekly hours'!H5=0," ",'weekly hours'!H5/8*'weekly hours'!H$2) -> 1340 | I5: =IF('weekly hours'!I5=0," ",'weekly hours'!I5/8*'weekly hours'!I$2) | J5: =IF('weekly hours'!J5=0," ",'weekly hours'!J5/8*'weekly hours'!J$2) | K5: =IF('weekly hours'!K5=0," ",'weekly hours'!K5/8*'weekly hours'!K$2) | ... V5: =IF('weekly hours'!V5=0," ",'weekly hours'!V5/8*'weekly hours'!V$2)
A6: ='weekly hours'!A6 -> 3 | B6: ='weekly hours'!B6 -> 45768 | C6: ='weekly hours'!C6 -> 45774 | D6: =IF('weekly hours'!D6=0," ",'weekly hours'!D6/8*'weekly hours'!D$2) | E6: =IF('weekly hours'!E6=0," ",'weekly hours'!E6/8*'weekly hours'!E$2) | F6: =IF('weekly hours'!F6=0," ",'weekly hours'!F6/8*'weekly hours'!F$2) | G6: =IF('weekly hours'!G6=0," ",'weekly hours'!G6/8*'weekly hours'!G$2) | H6: =IF('weekly hours'!H6=0," ",'weekly hours'!H6/8*'weekly hours'!H$2) | I6: =IF('weekly hours'!I6=0," ",'weekly hours'!I6/8*'weekly hours'!I$2) | J6: =IF('weekly hours'!J6=0," ",'weekly hours'!J6/8*'weekly hours'!J$2) | K6: =IF('weekly hours'!K6=0," ",'weekly hours'!K6/8*'weekly hours'!K$2) | ... V6: =IF('weekly hours'!V6=0," ",'weekly hours'!V6/8*'weekly hours'!V$2)
A7: ='weekly hours'!A7 -> 4 | B7: ='weekly hours'!B7 -> 45775 | C7: ='weekly hours'!C7 -> 45781 | D7: =IF('weekly hours'!D7=0," ",'weekly hours'!D7/8*'weekly hours'!D$2) | E7: =IF('weekly hours'!E7=0," ",'weekly hours'!E7/8*'weekly hours'!E$2) | F7: =IF('weekly hours'!F7=0," ",'weekly hours'!F7/8*'weekly hours'!F$2) | G7: =IF('weekly hours'!G7=0," ",'weekly hours'!G7/8*'weekly hours'!G$2) | H7: =IF('weekly hours'!H7=0," ",'weekly hours'!H7/8*'weekly hours'!H$2) | I7: =IF('weekly hours'!I7=0," ",'weekly hours'!I7/8*'weekly hours'!I$2) | J7: =IF('weekly hours'!J7=0," ",'weekly hours'!J7/8*'weekly hours'!J$2) | K7: =IF('weekly hours'!K7=0," ",'weekly hours'!K7/8*'weekly hours'!K$2) | ... V7: =IF('weekly hours'!V7=0," ",'weekly hours'!V7/8*'weekly hours'!V$2)
A8: ='weekly hours'!A8 -> 5 | B8: ='weekly hours'!B8 -> 45782 | C8: ='weekly hours'!C8 -> 45788 | D8: =IF('weekly hours'!D8=0," ",'weekly hours'!D8/8*'weekly hours'!D$2) | E8: =IF('weekly hours'!E8=0," ",'weekly hours'!E8/8*'weekly hours'!E$2) | F8: =IF('weekly hours'!F8=0," ",'weekly hours'!F8/8*'weekly hours'!F$2) | G8: =IF('weekly hours'!G8=0," ",'weekly hours'!G8/8*'weekly hours'!G$2) | H8: =IF('weekly hours'!H8=0," ",'weekly hours'!H8/8*'weekly hours'!H$2) | I8: =IF('weekly hours'!I8=0," ",'weekly hours'!I8/8*'weekly hours'!I$2) | J8: =IF('weekly hours'!J8=0," ",'weekly hours'!J8/8*'weekly hours'!J$2) | K8: =IF('weekly hours'!K8=0," ",'weekly hours'!K8/8*'weekly hours'!K$2) | ... V8: =IF('weekly hours'!V8=0," ",'weekly hours'!V8/8*'weekly hours'!V$2)
A9: ='weekly hours'!A9 -> 6 | B9: ='weekly hours'!B9 -> 45789 | C9: ='weekly hours'!C9 -> 45795 | D9: =IF('weekly hours'!D9=0," ",'weekly hours'!D9/8*'weekly hours'!D$2) | E9: =IF('weekly hours'!E9=0," ",'weekly hours'!E9/8*'weekly hours'!E$2) | F9: =IF('weekly hours'!F9=0," ",'weekly hours'!F9/8*'weekly hours'!F$2) | G9: =IF('weekly hours'!G9=0," ",'weekly hours'!G9/8*'weekly hours'!G$2) | H9: =IF('weekly hours'!H9=0," ",'weekly hours'!H9/8*'weekly hours'!H$2) | I9: =IF('weekly hours'!I9=0," ",'weekly hours'!I9/8*'weekly hours'!I$2) | J9: =IF('weekly hours'!J9=0," ",'weekly hours'!J9/8*'weekly hours'!J$2) | K9: =IF('weekly hours'!K9=0," ",'weekly hours'!K9/8*'weekly hours'!K$2) | ... V9: =IF('weekly hours'!V9=0," ",'weekly hours'!V9/8*'weekly hours'!V$2)
A10: ='weekly hours'!A10 -> 7 | B10: ='weekly hours'!B10 -> 45796 | C10: ='weekly hours'!C10 -> 45802 | D10: =IF('weekly hours'!D10=0," ",'weekly hours'!D10/8*'weekly hours'!D$2) | E10: =IF('weekly hours'!E10=0," ",'weekly hours'!E10/8*'weekly hours'!E$2) | F10: =IF('weekly hours'!F10=0," ",'weekly hours'!F10/8*'weekly hours'!F$2) | G10: =IF('weekly hours'!G10=0," ",'weekly hours'!G10/8*'weekly hours'!G$2) -> 838.75 | H10: =IF('weekly hours'!H10=0," ",'weekly hours'!H10/8*'weekly hours'!H$2) -> 2010 | I10: =IF('weekly hours'!I10=0," ",'weekly hours'!I10/8*'weekly hours'!I$2) | J10: =IF('weekly hours'!J10=0," ",'weekly hours'!J10/8*'weekly hours'!J$2) -> 536 | K10: =IF('weekly hours'!K10=0," ",'weekly hours'!K10/8*'weekly hours'!K$2) | ... V10: =IF('weekly hours'!V10=0," ",'weekly hours'!V10/8*'weekly hours'!V$2)
A11: ='weekly hours'!A11 -> 8 | B11: ='weekly hours'!B11 -> 45803 | C11: ='weekly hours'!C11 -> 45809 | D11: =IF('weekly hours'!D11=0," ",'weekly hours'!D11/8*'weekly hours'!D$2) | E11: =IF('weekly hours'!E11=0," ",'weekly hours'!E11/8*'weekly hours'!E$2) | F11: =IF('weekly hours'!F11=0," ",'weekly hours'!F11/8*'weekly hours'!F$2) | G11: =IF('weekly hours'!G11=0," ",'weekly hours'!G11/8*'weekly hours'!G$2) | H11: =IF('weekly hours'!H11=0," ",'weekly hours'!H11/8*'weekly hours'!H$2) | I11: =IF('weekly hours'!I11=0," ",'weekly hours'!I11/8*'weekly hours'!I$2) | J11: =IF('weekly hours'!J11=0," ",'weekly hours'!J11/8*'weekly hours'!J$2) | K11: =IF('weekly hours'!K11=0," ",'weekly hours'!K11/8*'weekly hours'!K$2) | ... V11: =IF('weekly hours'!V11=0," ",'weekly hours'!V11/8*'weekly hours'!V$2)
A12: ='weekly hours'!A12 -> 9 | B12: ='weekly hours'!B12 -> 45810 | C12: ='weekly hours'!C12 -> 45816 | D12: =IF('weekly hours'!D12=0," ",'weekly hours'!D12/8*'weekly hours'!D$2) | E12: =IF('weekly hours'!E12=0," ",'weekly hours'!E12/8*'weekly hours'!E$2) | F12: =IF('weekly hours'!F12=0," ",'weekly hours'!F12/8*'weekly hours'!F$2) | G12: =IF('weekly hours'!G12=0," ",'weekly hours'!G12/8*'weekly hours'!G$2) | H12: =IF('weekly hours'!H12=0," ",'weekly hours'!H12/8*'weekly hours'!H$2) | I12: =IF('weekly hours'!I12=0," ",'weekly hours'!I12/8*'weekly hours'!I$2) | J12: =IF('weekly hours'!J12=0," ",'weekly hours'!J12/8*'weekly hours'!J$2) | K12: =IF('weekly hours'!K12=0," ",'weekly hours'!K12/8*'weekly hours'!K$2) | ... V12: =IF('weekly hours'!V12=0," ",'weekly hours'!V12/8*'weekly hours'!V$2)
A13: ='weekly hours'!A13 -> 10 | B13: ='weekly hours'!B13 -> 45817 | C13: ='weekly hours'!C13 -> 45823 | D13: =IF('weekly hours'!D13=0," ",'weekly hours'!D13/8*'weekly hours'!D$2) | E13: =IF('weekly hours'!E13=0," ",'weekly hours'!E13/8*'weekly hours'!E$2) | F13: =IF('weekly hours'!F13=0," ",'weekly hours'!F13/8*'weekly hours'!F$2) | G13: =IF('weekly hours'!G13=0," ",'weekly hours'!G13/8*'weekly hours'!G$2) -> 838.75 | H13: =IF('weekly hours'!H13=0," ",'weekly hours'!H13/8*'weekly hours'!H$2) -> 1340 | I13: =IF('weekly hours'!I13=0," ",'weekly hours'!I13/8*'weekly hours'!I$2) | J13: =IF('weekly hours'!J13=0," ",'weekly hours'!J13/8*'weekly hours'!J$2) | K13: =IF('weekly hours'!K13=0," ",'weekly hours'!K13/8*'weekly hours'!K$2) | ... V13: =IF('weekly hours'!V13=0," ",'weekly hours'!V13/8*'weekly hours'!V$2)
A14: ='weekly hours'!A14 -> 11 | B14: ='weekly hours'!B14 -> 45824 | C14: ='weekly hours'!C14 -> 45830 | D14: =IF('weekly hours'!D14=0," ",'weekly hours'!D14/8*'weekly hours'!D$2) | E14: =IF('weekly hours'!E14=0," ",'weekly hours'!E14/8*'weekly hours'!E$2) | F14: =IF('weekly hours'!F14=0," ",'weekly hours'!F14/8*'weekly hours'!F$2) | G14: =IF('weekly hours'!G14=0," ",'weekly hours'!G14/8*'weekly hours'!G$2) | H14: =IF('weekly hours'!H14=0," ",'weekly hours'!H14/8*'weekly hours'!H$2) -> 1340 | I14: =IF('weekly hours'!I14=0," ",'weekly hours'!I14/8*'weekly hours'!I$2) | J14: =IF('weekly hours'!J14=0," ",'weekly hours'!J14/8*'weekly hours'!J$2) | K14: =IF('weekly hours'!K14=0," ",'weekly hours'!K14/8*'weekly hours'!K$2) | ... V14: =IF('weekly hours'!V14=0," ",'weekly hours'!V14/8*'weekly hours'!V$2)
A15: ='weekly hours'!A15 -> 12 | B15: ='weekly hours'!B15 -> 45831 | C15: ='weekly hours'!C15 -> 45837 | D15: =IF('weekly hours'!D15=0," ",'weekly hours'!D15/8*'weekly hours'!D$2) | E15: =IF('weekly hours'!E15=0," ",'weekly hours'!E15/8*'weekly hours'!E$2) | F15: =IF('weekly hours'!F15=0," ",'weekly hours'!F15/8*'weekly hours'!F$2) | G15: =IF('weekly hours'!G15=0," ",'weekly hours'!G15/8*'weekly hours'!G$2) | H15: =IF('weekly hours'!H15=0," ",'weekly hours'!H15/8*'weekly hours'!H$2) | I15: =IF('weekly hours'!I15=0," ",'weekly hours'!I15/8*'weekly hours'!I$2) | J15: =IF('weekly hours'!J15=0," ",'weekly hours'!J15/8*'weekly hours'!J$2) | K15: =IF('weekly hours'!K15=0," ",'weekly hours'!K15/8*'weekly hours'!K$2) | ... V15: =IF('weekly hours'!V15=0," ",'weekly hours'!V15/8*'weekly hours'!V$2)
... A71: ='weekly hours'!A71 -> 68 | B71: ='weekly hours'!B71 -> 46223 | C71: ='weekly hours'!C71 -> 46229 | D71: =IF('weekly hours'!D71=0," ",'weekly hours'!D71/8*'weekly hours'!D$2) | E71: =IF('weekly hours'!E71=0," ",'weekly hours'!E71/8*'weekly hours'!E$2) | F71: =IF('weekly hours'!F71=0," ",'weekly hours'!F71/8*'weekly hours'!F$2) | G71: =IF('weekly hours'!G71=0," ",'weekly hours'!G71/8*'weekly hours'!G$2) | H71: =IF('weekly hours'!H71=0," ",'weekly hours'!H71/8*'weekly hours'!H$2) | I71: =IF('weekly hours'!I71=0," ",'weekly hours'!I71/8*'weekly hours'!I$2) | J71: =IF('weekly hours'!J71=0," ",'weekly hours'!J71/8*'weekly hours'!J$2) | K71: =IF('weekly hours'!K71=0," ",'weekly hours'!K71/8*'weekly hours'!K$2) | ... V71: =IF('weekly hours'!V71=0," ",'weekly hours'!V71/8*'weekly hours'!V$2)
